names=cause
visibility=public
kind=defined

--- cause -> Exception | nil

self の前の例外(self が rescue 節や ensure 節の中で発生した例外の場合、
その前に発生していた元々の例外)を返します。存在しない場合は nil を返し
ます。

